Workbook

Sheet HO Group  
N1: يوم 2 اكتوبر | Q1: يوم 10 ديسمبر
B2: الإيرادات | C2: الشركة | D2: ملاحظات | J2: الإيرادات | L2: الارصده و الايردات المتوقعه | N2: الارصده و الايردات المتوقعه | Q2: الارصده و الايردات المتوقعه
B3: رصيد البنك الحالى | C3: UCP | J3: =120000+1200000 -> 1320000 | L3: 13554000 | N3: 13633000 | Q3: 0
B4: تحصيل عميل | C4: UCP | N4: 0 | Q4: 0
B5: تحصيل بيع الجملة | C5: UCP | Q5: 0
B6: رصيد خزينه | C6: uctd | L6: 0 | N6: 0 | Q6: 0
B7: رصيد البنك الحالى | C7: uctd | Q7: 10000000
B8: رصيد البنك الحالى | C8: MEC
B9: شيك تعويض التامين | C9: MEC | L9: 0 | N9: 1040000 | Q9: 21000000
B10: متحصلات نقدية متوقعة | C10: MEC | Q10: 0
B11: الاجمالى | J11: =SUM(J3:J10) -> 1320000 | L11: =SUM(L3:L10) -> 13554000 | N11: =SUM(N3:N10) -> 14673000 | Q11: =SUM(Q3:Q10) -> 31000000
B13: البيان | C13: الشركة | D13: المتاخرات | E13: المدفوع سبتمبر | F13: المتبقى حتى أغسطس 2025 | G13: قسط سبتمبر | H13: اجمالى المتاخرات | J13: المقترح سدادة | L13: المقترح سدادة | N13: المتفق على سداده | Q13: المطلوب سداده | S13: لاحقا
A14: وحدات مفيدا | B14: شركه ايزيليس | C14: UCP | D14: 2100000 | E14: =1500000+400000 -> 1900000 | F14: =D14-E14 -> 200000 | G14: 3686000 | H14: =3286000-1000000 -> 2286000 | L14: 200000 | N14: =+L14 -> 200000 | O14: تم السداد | Q14: 2500000 | R14: قسط شهر سبتمبر ( العقد كل 3 شهور) عدد 3 وحدات ( G03.A - 104m ) ( G02.B - 135m ) ( G03.E - 111m ) تخص الشركة المتحدة للصيادلة | S14: سداد بقية المبلغ قبل 15 ديسمبر
A15: صيدليه روفيد | B15: شركه هيرميس | C15: UCP | D15: =1537432-314527 -> 1222905 | E15: 0 | F15: =D15-E15 -> 1222905 | G15: 314527.12 | H15: 0 | L15: =+F15 -> 1222905 | Y15: سداد المتاخرات بدون شهر سبتمبر
B16: شركه انكوليس | C16: UCP | D16: =18600941+1677500-8600000 -> 11678441 | F16: =D16-E16 -> 11678441 | G16: 8600000 | H16: 20278441 | L16: 0 | R16: تخص ميدل ايست ويونى انفستمنت
A17: وحدات مفيدا | B17: شركه بدايه | C17: UCP | D17: =2230000*2 -> 4460000 | E17: 2230000 | F17: =D17-E17 -> 2230000 | G17: 2230000 | H17: =6690000-2230000 -> 4460000 | L17: 2230000 | Q17: 4208000 | R17: قسط شهر سبتمبر واكتوبر 2025 عبارة عن 4 وحدات مفيدا ( G03.D - 145m ) ( G03.C - 144m ) ( G03.B - 144m ) (G02.C- 153m) تخص الشركة المتحدة للصيادلة ( الشيكات شخصية باسم ايمن حسام) | Y17: سداد شهر أغسطس و باقى شهر سبتمبر و أكتوبر
A18: مخزن طنطا | B18: شركة التوفيق للتاجير التمويلى | C18: UCP | H18: 12600000 | R18: مهم جدآ- ا/ وليد رؤوف
B19: شركه الاهلى للتاجير التمويلى | C19: UCP | D19: 99087791 | E19: 1200000 | F19: =D19-E19 -> 97887791 | H19: =+'[1]الاهلى للتاجير التمويل'!$S$8+'[1]الاهلى للتاجير التمويل'!$T$8+'[1]الاهلى للتاجير التمويل'!$U$8+'[1]الاهلى للتاجير التمويل'!$S$27+'[1]الاهلى للتاجير التمويل'!$U$27 -> 76229769 | L19: 0 | R19: تخص ميدل ايست ويونى انفستمنت والمتحدة للصيادلة
B20: شركة اور للتاجير التمويلى والتخصيم | C20: UCP | H20: 78541654
B21: شركة بى ام للتاجير التمويلى | C21: UCP | Y21: يوجد مبلع 1739889 تخص يونى انفستمنت
B22: اويست | C22: UCP
B23: بروكس - فيلات | C23: UCP | H23: 44400000 | R23: لمنع فسخ عقود الفيلات
B24: حجز قضائى | C24: UCP | D24: =928681+1548095 -> 2476776 | F24: =D24-E24 -> 2476776 | H24: 13906000 | L24: =+H24 -> 13906000 | N24: 2476776 | O24: تم السداد | R24: وحدة مطالبات محكمة جنوب على حسابات بنوك المتحدة للصيادلة
B25: محكمة رسم نسبى ورسوم خدمات | C25: UCP | H25: =50000000-20000000 -> 30000000 | R25: تم دفع 5 مليون فى شهر نوفمبر 2025 والباقى 50 مليون تم دفع 20 مليون فى ديسمبر 2025 | U25: تم
B26: مرتبات شهر نوفمبر 2025 | C26: UCP | H26: =+'شرائح المرتبات 11 (الصيادلة)'!D13 -> 24063201 | Q26: =+'شرائح المرتبات 11 (الصيادلة)'!D6+'شرائح المرتبات 11 (الصيادلة)'!D7 -> 3989495 | T26: =+'شرائح المرتبات 11 (الصيادلة)'!F19 -> 2636677 | U26: تم
B27: شركة خزنه | C27: UCP | H27: 2000000 | L27: 200000 | N27: 0
B28: شركة وادى النيل | C28: UCP | H28: 7934867 | L28: 500000 | N28: 250000 | O28: تم السداد | T28: تم
B29: تمويل الخزينه | C29: UCP | D29: 200000 | F29: =D29-E29 -> 200000 | H29: 300000 | L29: 250000 | N29: 250000 | O29: تم السداد | Q29: 235000 | T29: تم | Y29: لترك الخدمة واخرى
A30: كسب الغير المشروع | B30: الشركة العربيه | C30: UCP | D30: 5000000 | F30: =D30-E30 -> 5000000 | G30: 5000000 | H30: 6000000 | L30: 0 | N30: 2000000 | O30: تم السداد | Q30: 2000000 | Y30: ايداع فى المحكمة
B31: مصنع فيتو فارم | C31: UCP | H31: 500000 | R31: مرتب شهر اغسطس 2025
B32: المساهمين | C32: UCP | U32: فبرابر | V32: مارس
B33: ايجار بولاريس الربع الرابع | C33: UCP | H33: =8500000-1000000 -> 7500000 | Q33: 2630000
B34: ايجار المنيا (المعونة الامريكية) | C34: UCP | D34: 690000 | F34: =D34-E34 -> 690000 | H34: 518727 | L34: 90000 | U34: =216629+114989 -> 331618 | V34: 216629
B35: اسيوط | C35: UCP | H35: 369233 | V35: =+V34+U34 -> 548247
B36: الاسماعيلية | C36: UCP | H36: 228108
B37: القومية | C37: UCP | H37: 158817 | Q37: 79408.5 | S37: 54460
B38: قليوب | C38: UCP | H38: 55527.906 | S38: 19000
B39: السويس | C39: UCP
B40: اسوان (حمزة) | C40: UCP | H40: =21962*4 -> 87848 | S40: 3000
B41: اسوان (عادل مصطفى) | C41: UCP | H41: 96000 | S41: 15000
...

Sheet شرائح المرتبات 9
K4: تفصيلى شرائح | L4: عدد موظفين | M4: مبلغ
K5: من 1 الى 5,000 | L5: 1895 | M5: 7374395
K6: من 5,001 الى 10,000 | L6: 1407 | M6: 9239185
K7: من 10,001 الى 15,000 | L7: 208 | M7: 2485087
K8: من 15,001 الى 20,000 | L8: 92 | M8: 1614458
K9: من 20,001 الى 25,000 | L9: 56 | M9: 1214961 | N9: =+M9+M8+M7 -> 5314506 | O9: =+N9/250000 -> 21.258024
K10: من 25,001 الى 30,000 | L10: 22 | M10: 618405
K11: من 30,001 الى 50,000 | L11: 28 | M11: 1004800
K12: من 50,001 الى 300,000 | L12: 23 | M12: 2296207 | N12: =+M12*0.7 -> 1607344.9
K13: الاجمالى | L13: =SUM(L5:L12) -> 3731 | M13: =SUM(M5:M12) -> 25847498
M14: =+M13-M5-M6 -> 9233918
M15: =+M14/250000 -> 36.935672

Sheet شرائح المرتبات 10
B3: تفصيلى شرائح | C3: عدد موظفين | D3: مبلغ
B4: من 1 الى 5,000 | C4: 1861 | D4: 7272118 | E4: 0.7 | F4: =+D4*E4 -> 5090482.6 | H4: =+D4-F4 -> 2181635.4
B5: من 5,001 الى 10,000 | C5: 1393 | D5: 9149905 | E5: 0.4 | F5: =+D5*E5 -> 3659962 | H5: =+D5-F5 -> 5489943
B6: من 10,001 الى 15,000 | C6: 205 | D6: 2445772 | E6: 0 | F6: =+D6*E6 -> 0 | H6: =+D6-F6 -> 2445772
B7: من 15,001 الى 20,000 | C7: 93 | D7: 1632410 | E7: 0 | F7: =+D7*E7 -> 0 | H7: =+D7-F7 -> 1632410
B8: من 20,001 الى 25,000 | C8: 55 | D8: 1191667 | E8: 0 | F8: =+D8*E8 -> 0 | H8: =+D8-F8 -> 1191667
B9: من 25,001 الى 30,000 | C9: 21 | D9: 588405 | E9: 0 | F9: =+D9*E9 -> 0 | H9: =+D9-F9 -> 588405
B10: من 30,001 الى 50,000 | C10: 29 | D10: 1034801 | E10: 0 | F10: =+D10*E10 -> 0 | H10: =+D10-F10 -> 1034801
B11: من 50,001 الى 100,000 | C11: 17 | D11: 1192790 | E11: 0 | F11: =+D11*E11 -> 0
B12: من 100,001 الى 300,000 | C12: 6 | D12: 1103416 | E12: 0 | F12: =+D12*E12 -> 0
B13: الاجمالى | C13: =SUM(C4:C12) -> 3680 | D13: =SUM(D4:D12) -> 25611284 | F13: =SUM(F4:F12) -> 8750444.6 | H13: =SUM(H4:H12) -> 14564633 | I13: =+#REF! -> #REF!
I14: =+H13-I13 -> #REF! | J14: الفرق عبارة عن خصومات من المرتب لعدم البصمة

Sheet شرائح المرتبات 11 (الصيادلة)
B3: تفصيلى شرائح | C3: عدد موظفين | D3: مبلغ | H3: موظف | I3: مرتب
B4: من 1 الى 5,000 | C4: 1905 | D4: 7022507 | E4: 0 | F4: =+D4*E4 -> 0 | H4: =+C4/$C$13 -> 0.53436185 | I4: =+D4/$D$13 -> 0.29183594
B5: من 5,001 الى 10,000 | C5: 1258 | D5: 8380877 | E5: 1 | F5: =+D5*E5 -> 8380877 | H5: =+C5/$C$13 -> 0.35287518 | I5: =+D5/$D$13 -> 0.34828604
B6: من 10,001 الى 15,000 | C6: 200 | D6: 2396334 | E6: 0 | F6: =+D6*E6 -> 0 | H6: =+C6/$C$13 -> 0.056100982 | I6: =+D6/$D$13 -> 0.099585005
B7: من 15,001 الى 20,000 | C7: 91 | D7: 1593161 | E7: 0 | F7: =+D7*E7 -> 0 | H7: =+C7/$C$13 -> 0.025525947 | I7: =+D7/$D$13 -> 0.06620736
B8: من 20,001 الى 25,000 | C8: 40 | D8: 872832 | E8: 0 | F8: =+D8*E8 -> 0 | H8: =+C8/$C$13 -> 0.011220196 | I8: =+D8/$D$13 -> 0.036272481
B9: من 25,001 الى 30,000 | C9: 21 | D9: 584564 | E9: 0 | F9: =+D9*E9 -> 0 | H9: =+C9/$C$13 -> 0.0058906031 | I9: =+D9/$D$13 -> 0.024292861
B10: من 30,001 الى 50,000 | C10: 28 | D10: 983445 | E10: 0 | F10: =+D10*E10 -> 0 | H10: =+C10/$C$13 -> 0.0078541374 | I10: =+D10/$D$13 -> 0.040869251
B11: من 50,001 الى 100,000 | C11: 16 | D11: 1127187 | E11: 0 | F11: =+D11*E11 -> 0 | H11: =+C11/$C$13 -> 0.0044880785 | I11: =+D11/$D$13 -> 0.04684277
B12: من 100,001 الى 300,000 | C12: 6 | D12: 1102294 | E12: 0 | F12: =+D12*E12 -> 0 | H12: =+C12/$C$13 -> 0.0016830295 | I12: =+D12/$D$13 -> 0.045808286
B13: الاجمالى | C13: =SUM(C4:C12) -> 3565 | D13: =SUM(D4:D12) -> 24063201 | F13: =SUM(F4:F12) -> 8380877 | H13: =+C13/$C$13 -> 1 | I13: =+D13/$D$13 -> 1
B18: تفصيلى شرائح | C18: عدد موظفين | D18: مبلغ | H18: موظف | I18: مرتب
B19: من 5,001 الى 60000 | C19: 480 | D19: 2636677 | E19: 1 | F19: =+D19*E19 -> 2636677 | H19: =+C19/$C$13 -> 0.13464236 | I19: =+D19/$D$13 -> 0.10957299
B20: من 6,001 الى 7,000 | C20: 366 | D20: 2379215 | E20: 0 | F20: =+D20*E20 -> 0 | H20: =+C20/$C$13 -> 0.1026648 | I20: =+D20/$D$13 -> 0.098873587
B21: من 7,001 الى 8,000 | C21: 207 | D21: 1538277 | E21: 0 | F21: =+D21*E21 -> 0 | H21: =+C21/$C$13 -> 0.058064516 | I21: =+D21/$D$13 -> 0.063926532
B22: من 8,001 الى 9,000 | C22: 113 | D22: 956203 | E22: 0 | F22: =+D22*E22 -> 0 | H22: =+C22/$C$13 -> 0.031697055 | I22: =+D22/$D$13 -> 0.039737149
B23: من 9,001 الى 10,000 | C23: 92 | D23: 870504 | E23: 0 | F23: =+D23*E23 -> 0 | H23: =+C23/$C$13 -> 0.025806452 | I23: =+D23/$D$13 -> 0.036175736
B24: الاجمالى | C24: =SUM(C19:C23) -> 1258 | D24: =SUM(D19:D23) -> 8380876 | F24: =SUM(F19:F23) -> 2636677 | H24: =+C24/$C$13 -> 0.35287518 | I24: =+D24/$D$13 -> 0.348286
C25: =+C24-C5 -> 0 | D25: =+D24-D5 -> -1

Sheet شرائح المرتبات 11 (شرق اوسط))
B3: تفصيلى شرائح | C3: عدد موظفين | D3: مبلغ | H3: موظف | I3: مرتب
B4: من 1 الى 5,000 | C4: 372 | D4: 1420211 | E4: 0 | F4: =+D4*E4 -> 0 | H4: =+C4/$C$13 -> 0.33066667 | I4: =+D4/$D$13 -> 0.15470713
B5: من 5,001 الى 10,000 | C5: 603 | D5: 3962276 | E5: 0 | F5: =+D5*E5 -> 0 | H5: =+C5/$C$13 -> 0.536 | I5: =+D5/$D$13 -> 0.43162062
B6: من 10,001 الى 15,000 | C6: 84 | D6: 1020718 | E6: 1 | F6: 0 | H6: =+C6/$C$13 -> 0.074666667 | I6: =+D6/$D$13 -> 0.11118936
B7: من 15,001 الى 20,000 | C7: 25 | D7: 419937 | E7: 1 | F7: 0 | H7: =+C7/$C$13 -> 0.022222222 | I7: =+D7/$D$13 -> 0.045744786
B8: من 20,001 الى 25,000 | C8: 11 | D8: 235314 | E8: 0 | F8: =+D8*E8 -> 0 | H8: =+C8/$C$13 -> 0.0097777778 | I8: =+D8/$D$13 -> 0.025633342
B9: من 25,001 الى 30,000 | C9: 5 | D9: 137368 | E9: 0 | F9: =+D9*E9 -> 0 | H9: =+C9/$C$13 -> 0.0044444444 | I9: =+D9/$D$13 -> 0.014963839
B10: من 30,001 الى 50,000 | C10: 9 | D10: 319859 | E10: 0 | F10: =+D10*E10 -> 0 | H10: =+C10/$C$13 -> 0.008 | I10: =+D10/$D$13 -> 0.03484304
B11: من 50,001 الى 100,000 | C11: 12 | D11: 789313 | E11: 0 | F11: =+D11*E11 -> 0 | H11: =+C11/$C$13 -> 0.010666667 | I11: =+D11/$D$13 -> 0.085981836
B12: من 100,001 الى 300,000 | C12: 4 | D12: 875001 | E12: 0 | F12: =+D12*E12 -> 0 | H12: =+C12/$C$13 -> 0.0035555556 | I12: =+D12/$D$13 -> 0.095316044
B13: الاجمالى | C13: =SUM(C4:C12) -> 1125 | D13: =SUM(D4:D12) -> 9179997 | F13: =SUM(F4:F12) -> 0 | H13: =+C13/$C$13 -> 1 | I13: =+D13/$D$13 -> 1
B18: تفصيلى شرائح | C18: عدد موظفين | D18: مبلغ | H18: موظف | I18: مرتب
B19: من 5,001 الى 60000 | C19: 222 | D19: 1204946 | E19: 1 | F19: =+D19*E19 -> 1204946 | H19: =+C19/$C$13 -> 0.19733333 | I19: =+D19/$D$13 -> 0.13125778
B20: من 6,001 الى 7,000 | C20: 197 | D20: 1271912 | E20: 0 | F20: =+D20*E20 -> 0 | H20: =+C20/$C$13 -> 0.17511111 | I20: =+D20/$D$13 -> 0.13855255
B21: من 7,001 الى 8,000 | C21: 105 | D21: 781670 | E21: 0 | F21: =+D21*E21 -> 0 | H21: =+C21/$C$13 -> 0.093333333 | I21: =+D21/$D$13 -> 0.085149265
B22: من 8,001 الى 9,000 | C22: 45 | D22: 380071 | E22: 0 | F22: =+D22*E22 -> 0 | H22: =+C22/$C$13 -> 0.04 | I22: =+D22/$D$13 -> 0.041402083
B23: من 9,001 الى 10,000 | C23: 34 | D23: 323677 | E23: 0 | F23: =+D23*E23 -> 0 | H23: =+C23/$C$13 -> 0.030222222 | I23: =+D23/$D$13 -> 0.035258944
B24: الاجمالى | C24: =SUM(C19:C23) -> 603 | D24: =SUM(D19:D23) -> 3962276 | F24: =SUM(F19:F23) -> 1204946 | H24: =+C24/$C$13 -> 0.536 | I24: =+D24/$D$13 -> 0.43162062
C25: =+C24-C5 -> 0 | D25: =+D24-D5 -> 0 | H25: =+H24-H5 -> 0 | I25: =+I24-I5 -> 0

Sheet شرائح المرتبات 11 (توزيع) (2)
B3: تفصيلى شرائح | C3: عدد موظفين | D3: مبلغ | H3: موظف | I3: مرتب
B4: من 1 الى 5,000 + 5% | C4: 273 | D4: 1079149.6 | E4: 0 | F4: =+D4*E4 -> 0 | H4: =+C4/$C$13 -> 0.37759336 | I4: =+D4/$D$13 -> 0.1695932
B5: من 5,001 الى 10,000 | C5: 320 | D5: 2127258 | E5: 1 | F5: =+D5*E5 -> 2127258 | H5: =+C5/$C$13 -> 0.44260028 | I5: =+D5/$D$13 -> 0.33430814
B6: من 10,001 الى 15,000 | C6: 51 | D6: 611213 | E6: 0 | F6: =+D6*E6 -> 0 | H6: =+C6/$C$13 -> 0.070539419 | I6: =+D6/$D$13 -> 0.096054866
B7: من 15,001 الى 20,000 | C7: 25 | D7: 427790 | E7: 0 | F7: =+D7*E7 -> 0 | H7: =+C7/$C$13 -> 0.034578147 | I7: =+D7/$D$13 -> 0.067229118
B8: من 20,001 الى 25,000 | C8: 13 | D8: 292165 | E8: 0 | F8: =+D8*E8 -> 0 | H8: =+C8/$C$13 -> 0.017980636 | I8: =+D8/$D$13 -> 0.045915041
B9: من 25,001 الى 30,000 | C9: 13 | D9: 354514.27 | E9: 0 | F9: =+D9*E9 -> 0 | H9: =+C9/$C$13 -> 0.017980636 | I9: =+D9/$D$13 -> 0.055713508
B10: من 30,001 الى 50,000 | C10: 22 | D10: 853510.55 | E10: 0 | F10: =+D10*E10 -> 0 | H10: =+C10/$C$13 -> 0.030428769 | I10: =+D10/$D$13 -> 0.13413301
B11: من 50,001 الى 100,000 | C11: 4 | D11: 277408 | E11: 0 | F11: =+D11*E11 -> 0 | H11: =+C11/$C$13 -> 0.0055325035 | I11: =+D11/$D$13 -> 0.043595912
B12: من 100,001 الى 300,000 | C12: 2 | D12: 340157 | E12: 0 | F12: =+D12*E12 -> 0 | H12: =+C12/$C$13 -> 0.0027662517 | I12: =+D12/$D$13 -> 0.053457199
B13: الاجمالى | C13: =SUM(C4:C12) -> 723 | D13: =SUM(D4:D12) -> 6363165.4 | F13: =SUM(F4:F12) -> 2127258 | H13: =+C13/$C$13 -> 1 | I13: =+D13/$D$13 -> 1
J14: الفرق عبارة عن خصومات من المرتب لعدم البصمة
B18: تفصيلى شرائح | C18: عدد موظفين | D18: مبلغ | H18: موظف | I18: مرتب
B19: من 5,001 الى 60000 | C19: 129 | D19: 706605 | E19: 1 | F19: =+D19*E19 -> 706605 | H19: =+C19/$C$13 -> 0.17842324 | I19: =+D19/$D$13 -> 0.11104615
B20: من 6,001 الى 7,000 | C20: 86 | D20: 553597 | E20: 0 | F20: =+D20*E20 -> 0 | H20: =+C20/$C$13 -> 0.11894882 | I20: =+D20/$D$13 -> 0.087000253
B21: من 7,001 الى 8,000 | C21: 45 | D21: 336362 | E21: 0 | F21: =+D21*E21 -> 0 | H21: =+C21/$C$13 -> 0.062240664 | I21: =+D21/$D$13 -> 0.052860798
B22: من 8,001 الى 9,000 | C22: 37 | D22: 312410 | E22: 0 | F22: =+D22*E22 -> 0 | H22: =+C22/$C$13 -> 0.051175657 | I22: =+D22/$D$13 -> 0.049096633
B23: من 9,001 الى 10,000 | C23: 23 | D23: 218284 | E23: 0 | F23: =+D23*E23 -> 0 | H23: =+C23/$C$13 -> 0.031811895 | I23: =+D23/$D$13 -> 0.03430431
B24: الاجمالى | C24: =SUM(C19:C23) -> 320 | D24: =SUM(D19:D23) -> 2127258 | F24: =SUM(F19:F23) -> 706605 | H24: =+C24/$C$13 -> 0.44260028 | I24: =+D24/$D$13 -> 0.33430814
C25: =+C24-C5 -> 0 | D25: =+D24-D5 -> 0 | H25: =+H24-H5 -> 0 | I25: =+I24-I5 -> 0

Sheet شرائح المرتبات مجموعة
C2: عدد الموظفين | G2: المرتبات | K2: عدد الموظفين % | O2: القيمة %
B3: تفصيلى شرائح | C3: المتحدة | D3: شرق اوسط | E3: توزيع | F3: اجمالى | G3: المتحدة | H3: شرق اوسط | I3: توزيع | J3: اجمالى | K3: المتحدة | L3: شرق اوسط | M3: توزيع | N3: اجمالى | O3: المتحدة | P3: شرق اوسط | Q3: توزيع | R3: اجمالى
B4: من 1 الى 5,000 + 5% | C4: =+'شرائح المرتبات 11 (الصيادلة)'!C4 -> 1905 | D4: =+'شرائح المرتبات 11 (شرق اوسط))'!C4 -> 372 | E4: =+'شرائح المرتبات 11 (توزيع) (2)'!C4 -> 273 | F4: =SUM(C4:E4) -> 2550 | G4: =+'شرائح المرتبات 11 (الصيادلة)'!D4 -> 7022507 | H4: =+'شرائح المرتبات 11 (شرق اوسط))'!D4 -> 1420211 | I4: =+'شرائح المرتبات 11 (توزيع) (2)'!D4 -> 1079149.6 | J4: =SUM(G4:I4) -> 9521867.6 | K4: =+C4/$C$13 -> 0.53436185 | L4: =+D4/$D$13 -> 0.33066667 | M4: =+E4/$E$13 -> 0.37759336 | N4: =+F4/$F$13 -> 0.47108812 | O4: =+G4/$G$13 -> 0.29183594 | P4: =+H4/$H$13 -> 0.15470713 | Q4: =+I4/$I$13 -> 0.1695932 | R4: =+J4/$J$13 -> 0.24041257
B5: من 5,001 الى 10,000 | C5: =+'شرائح المرتبات 11 (الصيادلة)'!C5 -> 1258 | D5: =+'شرائح المرتبات 11 (شرق اوسط))'!C5 -> 603 | E5: =+'شرائح المرتبات 11 (توزيع) (2)'!C5 -> 320 | F5: =SUM(C5:E5) -> 2181 | G5: =+'شرائح المرتبات 11 (الصيادلة)'!D5 -> 8380877 | H5: =+'شرائح المرتبات 11 (شرق اوسط))'!D5 -> 3962276 | I5: =+'شرائح المرتبات 11 (توزيع) (2)'!D5 -> 2127258 | J5: =SUM(G5:I5) -> 14470411 | K5: =+C5/$C$13 -> 0.35287518 | L5: =+D5/$D$13 -> 0.536 | M5: =+E5/$E$13 -> 0.44260028 | N5: =+F5/$F$13 -> 0.4029189 | O5: =+G5/$G$13 -> 0.34828604 | P5: =+H5/$H$13 -> 0.43162062 | Q5: =+I5/$I$13 -> 0.33430814 | R5: =+J5/$J$13 -> 0.36535571
B6: من 10,001 الى 15,000 | C6: =+'شرائح المرتبات 11 (الصيادلة)'!C6 -> 200 | D6: =+'شرائح المرتبات 11 (شرق اوسط))'!C6 -> 84 | E6: =+'شرائح المرتبات 11 (توزيع) (2)'!C6 -> 51 | F6: =SUM(C6:E6) -> 335 | G6: =+'شرائح المرتبات 11 (الصيادلة)'!D6 -> 2396334 | H6: =+'شرائح المرتبات 11 (شرق اوسط))'!D6 -> 1020718 | I6: =+'شرائح المرتبات 11 (توزيع) (2)'!D6 -> 611213 | J6: =SUM(G6:I6) -> 4028265 | K6: =+C6/$C$13 -> 0.056100982 | L6: =+D6/$D$13 -> 0.074666667 | M6: =+E6/$E$13 -> 0.070539419 | N6: =+F6/$F$13 -> 0.061888047 | O6: =+G6/$G$13 -> 0.099585005 | P6: =+H6/$H$13 -> 0.11118936 | Q6: =+I6/$I$13 -> 0.096054866 | R6: =+J6/$J$13 -> 0.10170752
B7: من 15,001 الى 20,000 | C7: =+'شرائح المرتبات 11 (الصيادلة)'!C7 -> 91 | D7: =+'شرائح المرتبات 11 (شرق اوسط))'!C7 -> 25 | E7: =+'شرائح المرتبات 11 (توزيع) (2)'!C7 -> 25 | F7: =SUM(C7:E7) -> 141 | G7: =+'شرائح المرتبات 11 (الصيادلة)'!D7 -> 1593161 | H7: =+'شرائح المرتبات 11 (شرق اوسط))'!D7 -> 419937 | I7: =+'شرائح المرتبات 11 (توزيع) (2)'!D7 -> 427790 | J7: =SUM(G7:I7) -> 2440888 | K7: =+C7/$C$13 -> 0.025525947 | L7: =+D7/$D$13 -> 0.022222222 | M7: =+E7/$E$13 -> 0.034578147 | N7: =+F7/$F$13 -> 0.026048402 | O7: =+G7/$G$13 -> 0.06620736 | P7: =+H7/$H$13 -> 0.045744786 | Q7: =+I7/$I$13 -> 0.067229118 | R7: =+J7/$J$13 -> 0.061628683
B8: من 20,001 الى 25,000 | C8: =+'شرائح المرتبات 11 (الصيادلة)'!C8 -> 40 | D8: =+'شرائح المرتبات 11 (شرق اوسط))'!C8 -> 11 | E8: =+'شرائح المرتبات 11 (توزيع) (2)'!C8 -> 13 | F8: =SUM(C8:E8) -> 64 | G8: =+'شرائح المرتبات 11 (الصيادلة)'!D8 -> 872832 | H8: =+'شرائح المرتبات 11 (شرق اوسط))'!D8 -> 235314 | I8: =+'شرائح المرتبات 11 (توزيع) (2)'!D8 -> 292165 | J8: =SUM(G8:I8) -> 1400311 | K8: =+C8/$C$13 -> 0.011220196 | L8: =+D8/$D$13 -> 0.0097777778 | M8: =+E8/$E$13 -> 0.017980636 | N8: =+F8/$F$13 -> 0.011823388 | O8: =+G8/$G$13 -> 0.036272481 | P8: =+H8/$H$13 -> 0.025633342 | Q8: =+I8/$I$13 -> 0.045915041 | R8: =+J8/$J$13 -> 0.035355707
B9: من 25,001 الى 30,000 | C9: =+'شرائح المرتبات 11 (الصيادلة)'!C9 -> 21 | D9: =+'شرائح المرتبات 11 (شرق اوسط))'!C9 -> 5 | E9: =+'شرائح المرتبات 11 (توزيع) (2)'!C9 -> 13 | F9: =SUM(C9:E9) -> 39 | G9: =+'شرائح المرتبات 11 (الصيادلة)'!D9 -> 584564 | H9: =+'شرائح المرتبات 11 (شرق اوسط))'!D9 -> 137368 | I9: =+'شرائح المرتبات 11 (توزيع) (2)'!D9 -> 354514.27 | J9: =SUM(G9:I9) -> 1076446.3 | K9: =+C9/$C$13 -> 0.0058906031 | L9: =+D9/$D$13 -> 0.0044444444 | M9: =+E9/$E$13 -> 0.017980636 | N9: =+F9/$F$13 -> 0.0072048771 | O9: =+G9/$G$13 -> 0.024292861 | P9: =+H9/$H$13 -> 0.014963839 | Q9: =+I9/$I$13 -> 0.055713508 | R9: =+J9/$J$13 -> 0.027178619
B10: من 30,001 الى 50,000 | C10: =+'شرائح المرتبات 11 (الصيادلة)'!C10 -> 28 | D10: =+'شرائح المرتبات 11 (شرق اوسط))'!C10 -> 9 | E10: =+'شرائح المرتبات 11 (توزيع) (2)'!C10 -> 22 | F10: =SUM(C10:E10) -> 59 | G10: =+'شرائح المرتبات 11 (الصيادلة)'!D10 -> 983445 | H10: =+'شرائح المرتبات 11 (شرق اوسط))'!D10 -> 319859 | I10: =+'شرائح المرتبات 11 (توزيع) (2)'!D10 -> 853510.55 | J10: =SUM(G10:I10) -> 2156814.5 | K10: =+C10/$C$13 -> 0.0078541374 | L10: =+D10/$D$13 -> 0.008 | M10: =+E10/$E$13 -> 0.030428769 | N10: =+F10/$F$13 -> 0.010899686 | O10: =+G10/$G$13 -> 0.040869251 | P10: =+H10/$H$13 -> 0.03484304 | Q10: =+I10/$I$13 -> 0.13413301 | R10: =+J10/$J$13 -> 0.054456263
B11: من 50,001 الى 100,000 | C11: =+'شرائح المرتبات 11 (الصيادلة)'!C11 -> 16 | D11: =+'شرائح المرتبات 11 (شرق اوسط))'!C11 -> 12 | E11: =+'شرائح المرتبات 11 (توزيع) (2)'!C11 -> 4 | F11: =SUM(C11:E11) -> 32 | G11: =+'شرائح المرتبات 11 (الصيادلة)'!D11 -> 1127187 | H11: =+'شرائح المرتبات 11 (شرق اوسط))'!D11 -> 789313 | I11: =+'شرائح المرتبات 11 (توزيع) (2)'!D11 -> 277408 | J11: =SUM(G11:I11) -> 2193908 | K11: =+C11/$C$13 -> 0.0044880785 | L11: =+D11/$D$13 -> 0.010666667 | M11: =+E11/$E$13 -> 0.0055325035 | N11: =+F11/$F$13 -> 0.0059116941 | O11: =+G11/$G$13 -> 0.04684277 | P11: =+H11/$H$13 -> 0.085981836 | Q11: =+I11/$I$13 -> 0.043595912 | R11: =+J11/$J$13 -> 0.055392816
B12: من 100,001 الى 300,000 | C12: =+'شرائح المرتبات 11 (الصيادلة)'!C12 -> 6 | D12: =+'شرائح المرتبات 11 (شرق اوسط))'!C12 -> 4 | E12: =+'شرائح المرتبات 11 (توزيع) (2)'!C12 -> 2 | F12: =SUM(C12:E12) -> 12 | G12: =+'شرائح المرتبات 11 (الصيادلة)'!D12 -> 1102294 | H12: =+'شرائح المرتبات 11 (شرق اوسط))'!D12 -> 875001 | I12: =+'شرائح المرتبات 11 (توزيع) (2)'!D12 -> 340157 | J12: =SUM(G12:I12) -> 2317452 | K12: =+C12/$C$13 -> 0.0016830295 | L12: =+D12/$D$13 -> 0.0035555556 | M12: =+E12/$E$13 -> 0.0027662517 | N12: =+F12/$F$13 -> 0.0022168853 | O12: =+G12/$G$13 -> 0.045808286 | P12: =+H12/$H$13 -> 0.095316044 | Q12: =+I12/$I$13 -> 0.053457199 | R12: =+J12/$J$13 -> 0.058512113
B13: الاجمالى | C13: =SUM(C4:C12) -> 3565 | D13: =SUM(D4:D12) -> 1125 | E13: =SUM(E4:E12) -> 723 | F13: =SUM(F4:F12) -> 5413 | G13: =SUM(G4:G12) -> 24063201 | H13: =SUM(H4:H12) -> 9179997 | I13: =SUM(I4:I12) -> 6363165.4 | J13: =SUM(J4:J12) -> 39606363 | K13: =SUM(K4:K12) -> 1 | L13: =+D13/$D$13 -> 1 | M13: =+E13/$E$13 -> 1 | N13: =+F13/$F$13 -> 1 | O13: =+G13/$G$13 -> 1 | P13: =+H13/$H$13 -> 1 | Q13: =+I13/$I$13 -> 1 | R13: =+J13/$J$13 -> 1
O14: =+O13-'شرائح المرتبات 11 (الصيادلة)'!L13 -> 1 | P14: =+P13-'شرائح المرتبات 11 (شرق اوسط))'!L13 -> 1 | Q14: =+Q13-'شرائح المرتبات 11 (توزيع) (2)'!L13 -> 1 | R14: =+R13-'شرائح المرتبات 11 (توزيع) (2)'!M13 -> 1
C17: عدد الموظفين | G17: المرتبات | K17: عدد الموظفين % | O17: القيمة %
B18: تفصيلى شرائح | C18: المتحدة | D18: شرق اوسط | E18: توزيع | F18: اجمالى | G18: المتحدة | H18: شرق اوسط | I18: توزيع | J18: اجمالى | K18: المتحدة | L18: شرق اوسط | M18: توزيع | N18: اجمالى | O18: المتحدة | P18: شرق اوسط | Q18: توزيع | R18: اجمالى
B19: من 5,001 الى 60000 | C19: =+'شرائح المرتبات 11 (الصيادلة)'!C19 -> 480 | D19: =+'شرائح المرتبات 11 (شرق اوسط))'!C19 -> 222 | E19: =+'شرائح المرتبات 11 (توزيع) (2)'!C19 -> 129 | F19: =SUM(C19:E19) -> 831 | G19: =+'شرائح المرتبات 11 (الصيادلة)'!D19 -> 2636677 | H19: =+'شرائح المرتبات 11 (شرق اوسط))'!D19 -> 1204946 | I19: =+'شرائح المرتبات 11 (توزيع) (2)'!D19 -> 706605 | J19: =SUM(G19:I19) -> 4548228 | K19: =+C19/$C$13 -> 0.13464236 | L19: =+D19/$D$13 -> 0.19733333 | M19: =+E19/$E$13 -> 0.17842324 | N19: =+F19/$F$13 -> 0.15351931 | O19: =+G19/$G$13 -> 0.10957299 | P19: =+H19/$H$13 -> 0.13125778 | Q19: =+I19/$I$13 -> 0.11104615 | R19: =+J19/$J$13 -> 0.11483579
B20: من 6,001 الى 7,000 | C20: =+'شرائح المرتبات 11 (الصيادلة)'!C20 -> 366 | D20: =+'شرائح المرتبات 11 (شرق اوسط))'!C20 -> 197 | E20: =+'شرائح المرتبات 11 (توزيع) (2)'!C20 -> 86 | F20: =SUM(C20:E20) -> 649 | G20: =+'شرائح المرتبات 11 (الصيادلة)'!D20 -> 2379215 | H20: =+'شرائح المرتبات 11 (شرق اوسط))'!D20 -> 1271912 | I20: =+'شرائح المرتبات 11 (توزيع) (2)'!D20 -> 553597 | J20: =SUM(G20:I20) -> 4204724 | K20: =+C20/$C$13 -> 0.1026648 | L20: =+D20/$D$13 -> 0.17511111 | M20: =+E20/$E$13 -> 0.11894882 | N20: =+F20/$F$13 -> 0.11989655 | O20: =+G20/$G$13 -> 0.098873587 | P20: =+H20/$H$13 -> 0.13855255 | Q20: =+I20/$I$13 -> 0.087000253 | R20: =+J20/$J$13 -> 0.10616284
B21: من 7,001 الى 8,000 | C21: =+'شرائح المرتبات 11 (الصيادلة)'!C21 -> 207 | D21: =+'شرائح المرتبات 11 (شرق اوسط))'!C21 -> 105 | E21: =+'شرائح المرتبات 11 (توزيع) (2)'!C21 -> 45 | F21: =SUM(C21:E21) -> 357 | G21: =+'شرائح المرتبات 11 (الصيادلة)'!D21 -> 1538277 | H21: =+'شرائح المرتبات 11 (شرق اوسط))'!D21 -> 781670 | I21: =+'شرائح المرتبات 11 (توزيع) (2)'!D21 -> 336362 | J21: =SUM(G21:I21) -> 2656309 | K21: =+C21/$C$13 -> 0.058064516 | L21: =+D21/$D$13 -> 0.093333333 | M21: =+E21/$E$13 -> 0.062240664 | N21: =+F21/$F$13 -> 0.065952337 | O21: =+G21/$G$13 -> 0.063926532 | P21: =+H21/$H$13 -> 0.085149265 | Q21: =+I21/$I$13 -> 0.052860798 | R21: =+J21/$J$13 -> 0.067067733
B22: من 8,001 الى 9,000 | C22: =+'شرائح المرتبات 11 (الصيادلة)'!C22 -> 113 | D22: =+'شرائح المرتبات 11 (شرق اوسط))'!C22 -> 45 | E22: =+'شرائح المرتبات 11 (توزيع) (2)'!C22 -> 37 | F22: =SUM(C22:E22) -> 195 | G22: =+'شرائح المرتبات 11 (الصيادلة)'!D22 -> 956203 | H22: =+'شرائح المرتبات 11 (شرق اوسط))'!D22 -> 380071 | I22: =+'شرائح المرتبات 11 (توزيع) (2)'!D22 -> 312410 | J22: =SUM(G22:I22) -> 1648684 | K22: =+C22/$C$13 -> 0.031697055 | L22: =+D22/$D$13 -> 0.04 | M22: =+E22/$E$13 -> 0.051175657 | N22: =+F22/$F$13 -> 0.036024386 | O22: =+G22/$G$13 -> 0.039737149 | P22: =+H22/$H$13 -> 0.041402083 | Q22: =+I22/$I$13 -> 0.049096633 | R22: =+J22/$J$13 -> 0.041626745
B23: من 9,001 الى 10,000 | C23: =+'شرائح المرتبات 11 (الصيادلة)'!C23 -> 92 | D23: =+'شرائح المرتبات 11 (شرق اوسط))'!C23 -> 34 | E23: =+'شرائح المرتبات 11 (توزيع) (2)'!C23 -> 23 | F23: =SUM(C23:E23) -> 149 | G23: =+'شرائح المرتبات 11 (الصيادلة)'!D23 -> 870504 | H23: =+'شرائح المرتبات 11 (شرق اوسط))'!D23 -> 323677 | I23: =+'شرائح المرتبات 11 (توزيع) (2)'!D23 -> 218284 | J23: =SUM(G23:I23) -> 1412465 | K23: =+C23/$C$13 -> 0.025806452 | L23: =+D23/$D$13 -> 0.030222222 | M23: =+E23/$E$13 -> 0.031811895 | N23: =+F23/$F$13 -> 0.027526326 | O23: =+G23/$G$13 -> 0.036175736 | P23: =+H23/$H$13 -> 0.035258944 | Q23: =+I23/$I$13 -> 0.03430431 | R23: =+J23/$J$13 -> 0.035662577
B24: الاجمالى | C24: =SUM(C19:C23) -> 1258 | D24: =SUM(D19:D23) -> 603 | E24: =SUM(E19:E23) -> 320 | F24: =SUM(F19:F23) -> 2181 | G24: =SUM(G19:G23) -> 8380876 | H24: =SUM(H19:H23) -> 3962276 | I24: =SUM(I19:I23) -> 2127258 | J24: =SUM(J19:J23) -> 14470410 | K24: =+C24/$C$13 -> 0.35287518 | L24: =+D24/$D$13 -> 0.536 | M24: =+E24/$E$13 -> 0.44260028 | N24: =+F24/$F$13 -> 0.4029189 | O24: =+G24/$G$13 -> 0.348286 | P24: =+H24/$H$13 -> 0.43162062 | Q24: =+I24/$I$13 -> 0.33430814 | R24: =+J24/$J$13 -> 0.36535568
C25: =+C24-C5 -> 0 | D25: =+D24-D5 -> 0 | E25: =+E24-E5 -> 0 | F25: =+F24-F5 -> 0 | G25: =+G24-G5 -> -1 | H25: =+H24-H5 -> 0 | I25: =+I24-I5 -> 0 | J25: =+J24-J5 -> -1 | ... R25: =+R24-R5 -> -2.5248468e-08

Sheet المتاخرات
A2: الفرع | B2: المكان | C2: المؤجر | D2: حساب المؤجر | E2: الحاله | F2: شهر الاستحقاق | K2: الاجمالى
F3: 45809 | G3: 45839 | H3: 45870 | I3: 45901 | J3: 45931
A4: اسيوط | B4: مخزن اصناف | C4: احمد حنفى محمود ناصر | D4: 10096 | E4: لم يسدد | F4: 0 | G4: 0 | H4: 0 | I4: 0 | J4: 18232.6 | K4: =SUM(F4:J4) -> 18232.6
A5: اسيوط | B5: محل | C5: شاديه محمود حسن حسانين | D5: 10097 | E5: لم يسدد | I5: 175500 | J5: 175500 | K5: =SUM(F5:J5) -> 351000
A6: الاسماعيليه | B6: شقتين | C6: عفاف احمد حسن عوضالله | D6: 10029 | E6: لم يسدد | I6: 19326.12 | J6: 19326.12 | K6: =SUM(F6:J6) -> 38652.24
A7: الاسماعيليه | B7: مخزن | C7: عادل عزيز وديع فهمى | D7: 10030 | E7: لم يسدد | H7: 38600 | I7: 36800 | J7: 36800 | K7: =SUM(F7:J7) -> 112200
A8: الاسماعيليه | B8: مخزن | C8: محمد صالح عبد الله رجب | D8: 10031 | E8: لم يسدد | I8: 0 | J8: 44149.32 | K8: =SUM(F8:J8) -> 44149.32
A9: الاسماعيليه | B9: شقة | C9: محمد صالح عبدالله رجب | D9: 10031 | E9: لم يسدد | J9: 6753.2866 | K9: =SUM(F9:J9) -> 6753.2866
A10: الاسماعيليه | B10: شقة | C10: سليمان فواد السيد خليل يوسف | D10: 10032 | E10: لم يسدد | H10: 8784.5 | I10: 8784.5 | J10: 8784.5 | K10: =SUM(F10:J10) -> 26353.5
A11: القوميه | B11: مخزن/2شقة | C11: محمد جمال السيد حسن | D11: 10025 | E11: لم يسدد | F11: 0 | G11: 0 | H11: 0 | I11: 79408.4 | J11: 79408.4 | K11: =SUM(F11:J11) -> 158816.8
A12: قليوب | B12: مخزن | C12: هانى عبد الخالق سيد محمد | D12: 10028 | E12: لم يسدد | F12: 0 | G12: 0 | H12: 0 | I12: 0 | J12: 55527.906 | K12: =SUM(F12:J12) -> 55527.906
F13: =SUM(F4:F12) -> 0 | G13: =SUM(G4:G12) -> 0 | H13: =SUM(H4:H12) -> 47384.5 | I13: =SUM(I4:I12) -> 319819.02 | J13: =SUM(J4:J12) -> 444482.13 | K13: =SUM(F13:J13) -> 811685.65

Sheet UCTD
B2: البيان | C2: القيمة | D2: قيمة القسط | E2: عدد الاقساط | F2: التاريخ
B3: اورانج | C3: 146959.73 | F3: 45799
B4: اورانج | C4: 150655.38 | F4: 45830
B5: اورانج | C5: 125607.08 | F5: 45859
B6: اورانج | C6: 133787.94 | F6: 45890
B7: Total | C7: =SUM(C3:C6) -> 557010.13
B8: توتال | C8: 48965 | F8: 45823
B9: توتال | C9: 54630.2 | F9: 45838
B10: توتال | C10: 62035.69 | F10: 45853
B11: توتال | C11: 60274.58 | F11: 45869
B12: Total | C12: =SUM(C8:C11) -> 225905.47
B13: شركة النيل للزيوت والمنظفات ( ايجار سوهاج ) | C13: =+D13*E13 -> 1213055 | D13: 242611 | E13: 5 | F13: يونية/يوليو/اغسطس/سبتمبر/اكتوبر | G13: =+C13/E13 -> 242611 | H13: =+G13*2 -> 485222
B14: مصطفى امين حجازى ( ايجار المنصورة ) | C14: =+D14*E14 -> 1452000 | D14: 290400 | E14: 5 | F14: يونية/يوليو/اغسطس/سبتمبر/اكتوبر | G14: =+C14/E14 -> 290400 | H14: =+G14*2 -> 580800
B15: شركة الجمهورية ( ايجار الاسكندرية ) | C15: =+D15*E15 -> 1273836 | D15: 212306 | E15: 6 | F15: مايو/يونية/يوليو/اغسطس/سبتمبر/اكتوبر | G15: =+C15/E15 -> 212306 | H15: =+G15*2 -> 424612
B16: بولاريس ( ايجار مخزن اكتوبر ) | C16: =+D16*E16 -> 3898800 | D16: 1299600 | E16: 3 | F16: ابريل/يوليو/اكتوبر | G16: =+C16/E16 -> 1299600 | H16: =+G16*1 -> 1299600
B17: حسين كمال ابوكريشة ( ايجار سوهاج ) | C17: =+D17*E17 -> 70057.19 | D17: 70057.19 | E17: 1 | F17: اكتوبر | G17: =+C17/E17 -> 70057.19 | H17: =+G17*1 -> 70057.19
B18: ايجار فرع السواح | C18: 3150000 | H18: 1000000
B19: Total | C19: =SUM(C13:C18) -> 11057748
B20: مرتبات شهر اغسطس | C20: 2500000 | F20: اغسطس 2025
B21: مرتبات شهر سبتمبر | C21: 7500000 | F21: سبتمبر 2025
B22: تامينات التجارة& التوزيع | C22: =3800000+1750000 -> 5550000
B23: Total | C23: =SUM(C20:C22) -> 15550000 | D23: =SUM(D20:D22) -> 0
B24: شيكات أوراق الدفع المستحقة - شركات التاجير التمويلى
B25: شركة التوفيق للتاجير التمويلى | C25: 25783995 | F25: مرفق تفصيل الرصيد
B26: شركة اور للتاجير التمويلى والتخصيم | C26: 29122009 | F26: مرفق تفصيل الرصيد
B27: شركة الاهلى للتاجير التمويلى | C27: 13655884 | F27: مرفق تفصيل الرصيد
B28: شركة بلتون للتاجير التمويلى والتخصيم | C28: 16504097 | F28: مرفق تفصيل الرصيد
B29: شركة بى ام للتاجير التمويلى | C29: 8811090 | F29: مرفق تفصيل الرصيد
B30: الاجمالى | C30: =C23+C19+C12+C7+C25+C26+C27+C28+C29 -> 121267739
C35: شيكات أوراق الدفع المستحقة - شركات التاجير التمويلى | F35: 45932.114
C36: الشركة | D36: اجمالى قيمة الشيكات | E36: اجمالى المسدد من المرتد | F36: المتبقى من المرتد
C37: شركة التوفيق للتاجير التمويلى | D37: 1.0368761e+08 | E37: 77903613 | F37: =D37-E37 -> 25783995
C38: شركة اور للتاجير التمويلى والتخصيم | D38: 31500631 | E38: 812319 | F38: 29122009
C39: شركة الاهلى للتاجير التمويلى | D39: 40694006 | E39: 27038122 | F39: =D39-E39 -> 13655884
C40: شركة بلتون للتاجير التمويلى والتخصيم | D40: 24220450 | E40: 7716353 | F40: =D40-E40 -> 16504097
C41: شركة بى ام للتاجير التمويلى | D41: 15633492 | E41: 6822402 | F41: =D41-E41 -> 8811090
C42: شركة الأهلى الكويتى - مصر للتأجير التمويلى | D42: 2665439 | E42: 2665439 | F42: =D42-E42 -> 0
C43: الاجمالى | D43: =SUM(D37:D42) -> 2.1840163e+08 | E43: =SUM(E37:E42) -> 1.2295825e+08 | F43: =SUM(F37:F42) -> 93877075

Sheet التوفيق
B2: شركة التوفيق للتاجير التمويلى
B3: تاريخ الاستحقاق | C3: رقم الشيك | D3: البنك | E3: قيمة الشيك
B4: 45777 | C4: 2926230 | D4: ARAB_002 | E4: 8653843
B5: 45843 | C5: 2880706 | D5: ARAB_002 | E5: 3765420
B6: 45843 | C6: 2925810 | D6: ARAB_002 | E6: 269210
B7: 45843 | C7: 2948484 | D7: ARAB_002 | E7: 184824
B8: 45843 | C8: 2948915 | D8: ARAB_002 | E8: 285022
B9: 45843 | C9: 2949338 | D9: ARAB_002 | E9: 195058
B10: 45843 | C10: 3001368 | D10: ARAB_002 | E10: 893333
B11: 45869 | C11: 2926231 | D11: ARAB_002 | E11: 8653843
B12: 45869 | C12: 2948940 | D12: ARAB_002 | E12: 986330
B13: 45869 | C13: 2949292 | D13: ARAB_002 | E13: 386332
B14: 45869 | C14: 2949622 | D14: ARAB_002 | E14: 178497
B15: 45869 | C15: 3001353 | D15: ARAB_002 | E15: 1332283
B16: الاجمالى | E16: =SUM(E4:E15) -> 25783995
E17: =E16-UCTD!F37 -> 0

Sheet اور
B2: شركة اور للتاجير التمويلى والتخصيم
B3: تاريخ الاستحقاق | C3: رقم الشيك | D3: البنك | E3: قيمة الشيك
B4: 45672 | C4: 1097008 | D4: BRCLYS_001 | E4: 3517176.5
B5: 45672 | C5: 1097009 | D5: BRCLYS_001 | E5: 4577528.7
B6: 45708 | C6: 1096958 | D6: BRCLYS_001 | E6: 4577528.7
B7: 45713 | C7: 1096959 | D7: BRCLYS_001 | E7: 3714432.2
B8: 45736 | C8: 1096960 | D8: BRCLYS_001 | E8: 4577528.7
B9: 45741 | C9: 1096961 | D9: BRCLYS_001 | E9: 2118651.6
B10: 45767 | C10: 1096962 | D10: BRCLYS_001 | E10: 3714432.2
B11: 45772 | C11: 1096963 | D11: BRCLYS_001 | E11: 2118651.6
B12: 45741 | C12: 2949690 | D12: ARAB_002 | E12: 916
B13: 45741 | C13: 2949442 | D13: ARAB_002 | E13: 2030
B14: 45741 | C14: 3001509 | D14: ARAB_002 | E14: 6245
B15: 45741 | C15: 2948832 | D15: ARAB_002 | E15: 59502
... B23: 45925 | C23: 3001511 | D23: ARAB_002 | E23: 6245
B24: الاجمالى | E24: =SUM(E4:E23) -> 29122009
E25: =E24-UCTD!F38 -> 0

Sheet الاهلى 
B2: شركة الاهلى للتاجير التمويلى
B3: تاريخ الاستحقاق | C3: رقم الشيك | D3: البنك | E3: قيمة الشيك
B4: 45531 | C4: 2847848 | D4: ARAB_002 | E4: 2392612
B5: 45623 | C5: 2847849 | D5: ARAB_002 | E5: 2392612
B6: 45623 | C6: 2847877 | D6: ARAB_002 | E6: 217592
B7: 45623 | C7: 2925371 | D7: ARAB_002 | E7: 61622
B8: 45623 | C8: 2925397 | D8: ARAB_002 | E8: 6146
B9: 45623 | C9: 2925505 | D9: ARAB_002 | E9: 12561
B10: 45623 | C10: 2925707 | D10: ARAB_002 | E10: 125285
B11: 45715 | C11: 2847850 | D11: ARAB_002 | E11: 2392612
B12: 45715 | C12: 2847878 | D12: ARAB_002 | E12: 217592
B13: 45715 | C13: 2925372 | D13: ARAB_002 | E13: 61622
B14: 45715 | C14: 2925398 | D14: ARAB_002 | E14: 6146
B15: 45715 | C15: 2925506 | D15: ARAB_002 | E15: 12561
... B28: 45896 | C28: 2925710 | D28: ARAB_002 | E28: 125285
B29: الاجمالى | E29: =SUM(E4:E28) -> 13655884
E30: =E29-UCTD!F39 -> 0

Sheet بى ام
B2: شركة بى ام للتاجير التمويلى
B3: تاريخ الاستحقاق | C3: رقم الشيك | D3: البنك | E3: قيمة الشيك
B4: 45736 | C4: 2848304 | D4: ARAB_002 | E4: 1942686
B5: 45736 | C5: 2948461 | D5: ARAB_002 | E5: 288631
B6: 45736 | C6: 2948859 | D6: ARAB_002 | E6: 169845
B7: 45736 | C7: 2949128 | D7: ARAB_002 | E7: 106377
B8: 45736 | C8: 3000625 | D8: ARAB_002 | E8: 48423
B9: 45736 | C9: 3001173 | D9: ARAB_002 | E9: 89701
B10: 45736 | C10: 3001308 | D10: ARAB_002 | E10: 291367
B11: 45828 | C11: 2848305 | D11: ARAB_002 | E11: 1942686
B12: 45828 | C12: 2948462 | D12: ARAB_002 | E12: 288631
B13: 45828 | C13: 2948860 | D13: ARAB_002 | E13: 169845
B14: 45828 | C14: 2949129 | D14: ARAB_002 | E14: 106377
B15: 45828 | C15: 3000626 | D15: ARAB_002 | E15: 48423
... B24: 45920 | C24: 3001310 | D24: ARAB_002 | E24: 291367
B25: الاجمالى | E25: =SUM(E4:E24) -> 8811090
E26: =E25-UCTD!F41 -> 0

Sheet بلتون
B2: شركة بلتون للتاجير التمويلى والتخصيم
B3: تاريخ الاستحقاق | C3: رقم الشيك | D3: البنك | E3: قيمة الشيك
B4: 45646 | C4: 2848346 | D4: ARAB_002 | E4: 2720651
B5: 45646 | C5: 2848346 | D5: ARAB_002 | E5: -700000
B6: 45646 | C6: 2848346 | D6: ARAB_002 | E6: -500000
B7: 45641 | C7: 2847484 | D7: ARAB_002 | E7: 72126
B8: 45641 | C8: 3001127 | D8: ARAB_002 | E8: 6076
B9: 45641 | C9: 3001246 | D9: ARAB_002 | E9: 16503
B10: 45641 | C10: 3001254 | D10: ARAB_002 | E10: 4057
B11: 45646 | C11: 2925957 | D11: ARAB_002 | E11: 142686
B12: 45646 | C12: 2948669 | D12: ARAB_002 | E12: 400274
B13: 45646 | C13: 2949192 | D13: ARAB_002 | E13: 158581
B14: 45646 | C14: 3000715 | D14: ARAB_002 | E14: 67813
B15: 45646 | C15: 3001149 | D15: ARAB_002 | E15: 123830
... B126: 45925 | C126: 3001273 | D126: ARAB_002 | E126: 1592
B127: الاجمالى | E127: =SUM(E4:E126) -> 16504097
E128: =E127-UCTD!F40 -> 0

Sheet MEC
B2: من تاريخ 01-01-2025 الى 10-10-2025
B3: البيان | C3: الايرادات
B5: البنك | C5: 10000000
B6: باقى شيكات أمون | C6: 15000000 | E6: شراء بضاعة للتشغيل
B8: البيان | C8: =SUM(C5:C7) -> 25000000
B10: البيان | C10: المدفوعات
B11: ان أية كيمكال | C11: 39606.5
B12: الرواد | C12: 51917.15
B13: ضرائب عقارية | C13: 148242
B14: سى دى تى للحلول الاستشارية | C14: 399600
B15: ضريبة القيمة المضافة | C15: 1160385.6
B16: ضريبة الجدول | C16: 470538.38
B17: ضريبة كسب العمل | C17: 1100000
B18: بدلات وانتقالات | C18: 309345
B19: تسويات نهاية الخدمة | C19: 750000
B20: ايجار تمويلى - انكوليس | C20: 1011897
B21: ايجار تمويلى كوربليس | C21: 793116
B22: مكتب التأمينات | C22: 2200000
... B30: ايجارات | C30: 2244172
B31: تكلفة باصات | C31: =28675+27621+44185+124763+73692 -> 298936
B32: صندوق الشهداء | C32: 6324
B33: صندوق الطوارى | C33: =19445+685 -> 20130
B34: كهرباء | C34: =166914+48722+101537+540000+50000 -> 907173
B35: اتصالات | C35: 14065
B36: أورانج | C36: 134166
B37: تمويل خزينة | C37: 300000
B38: متنوعات | C38: 50000
B39: فواد بنك تنمية الصادرات | C39: 750000
C40: =SUM(C11:C39) -> 65633294
C42: =C8-C40 -> -40633294
